<?xml version="1.0"?>
<robot name="hunter_vehicle">
  
  <!-- Base Link (Hunter 차량 중심) -->
  <link name="base_link">
    <visual>
      <geometry>
        <box size="0.65 0.605 0.55"/>  <!-- wheelbase x track x height -->
      </geometry>
      <material name="hunter_blue">
        <color rgba="0.1 0.3 0.8 1"/>
      </material>
    </visual>
    <collision>
      <geometry>
        <box size="0.65 0.605 0.55"/>
      </geometry>
    </collision>
    <inertial>
      <mass value="80"/>  <!-- Hunter 실제 무게 고려 -->
      <inertia ixx="3.0" ixy="0.0" ixz="0.0" iyy="4.0" iyz="0.0" izz="5.0"/>
    </inertial>
  </link>

  <!-- IMU Link -->
  <link name="imu_link">
    <visual>
      <geometry>
        <box size="0.05 0.05 0.02"/>
      </geometry>
      <material name="red">
        <color rgba="0.8 0.2 0.2 1"/>
      </material>
    </visual>
  </link>

  <!-- Ouster Sensor Link -->
  <link name="os_sensor">
    <visual>
      <geometry>
        <cylinder radius="0.05" length="0.08"/>
      </geometry>
      <material name="black">
        <color rgba="0.1 0.1 0.1 1"/>
      </material>
    </visual>
  </link>

  <!-- 바퀴들 추가 -->
  <!-- 전륜 좌측 -->
  <link name="front_left_wheel">
    <visual>
      <geometry>
        <cylinder radius="0.165" length="0.1"/>
      </geometry>
      <material name="wheel_black">
        <color rgba="0.2 0.2 0.2 1"/>
      </material>
    </visual>
  </link>

  <!-- 전륜 우측 -->
  <link name="front_right_wheel">
    <visual>
      <geometry>
        <cylinder radius="0.165" length="0.1"/>
      </geometry>
      <material name="wheel_black">
        <color rgba="0.2 0.2 0.2 1"/>
      </material>
    </visual>
  </link>

  <!-- 후륜 좌측 -->
  <link name="rear_left_wheel">
    <visual>
      <geometry>
        <cylinder radius="0.165" length="0.1"/>
      </geometry>
      <material name="wheel_black">
        <color rgba="0.2 0.2 0.2 1"/>
      </material>
    </visual>
  </link>

  <!-- 후륜 우측 -->
  <link name="rear_right_wheel">
    <visual>
      <geometry>
        <cylinder radius="0.165" length="0.1"/>
      </geometry>
      <material name="wheel_black">
        <color rgba="0.2 0.2 0.2 1"/>
      </material>
    </visual>
  </link>

  <!-- Joints -->
  <!-- Base to IMU Joint -->
  <joint name="base_to_imu" type="fixed">
    <parent link="base_link"/>
    <child link="imu_link"/>
    <origin xyz="0 0 0" rpy="0 0 0"/>
  </joint>

  <!-- Base to Ouster Joint (지면에서 55cm = base_link 중심에서 27.5cm 위) -->
  <joint name="base_to_ouster" type="fixed">
    <parent link="base_link"/>
    <child link="os_sensor"/>
    <origin xyz="0 0 0.275" rpy="0 0 0"/>
  </joint>

  <!-- 바퀴 조인트들 -->
  <joint name="front_left_wheel_joint" type="continuous">
    <parent link="base_link"/>
    <child link="front_left_wheel"/>
    <origin xyz="0.325 0.3025 -0.275" rpy="1.5708 0 0"/>
    <axis xyz="0 0 1"/>
  </joint>

  <joint name="front_right_wheel_joint" type="continuous">
    <parent link="base_link"/>
    <child link="front_right_wheel"/>
    <origin xyz="0.325 -0.3025 -0.275" rpy="1.5708 0 0"/>
    <axis xyz="0 0 1"/>
  </joint>

  <joint name="rear_left_wheel_joint" type="continuous">
    <parent link="base_link"/>
    <child link="rear_left_wheel"/>
    <origin xyz="-0.325 0.3025 -0.275" rpy="1.5708 0 0"/>
    <axis xyz="0 0 1"/>
  </joint>

  <joint name="rear_right_wheel_joint" type="continuous">
    <parent link="base_link"/>
    <child link="rear_right_wheel"/>
    <origin xyz="-0.325 -0.3025 -0.275" rpy="1.5708 0 0"/>
    <axis xyz="0 0 1"/>
  </joint>

</robot>